Workbook

Sheet Sheet1
K5: Compute
K6: 120 | L6: 120 | M6: 9 | N6: CRM Cost
B7: ESDS' eNlight Cloud Hosting Services - (ESDS DC) | K7: 75 | L7: 75 | M7: 4 | N7: Fixed rate card | O7: 45 | P7: 45 | Q7: 2
B8: Env. | C8: Hosting Components | K8: vCores | L8: RAM | M8: HDD
B9: A.1 | C9: eNlight Cloud Hosting | D9: Unit | E9: Cost/Unit Per Month | F9: Discounted Cost/Unit Per Month | G9: MRC Cost | H9: Discounted MRC Cost | I9: OTC | J9: Comment | K9: No | L9: GB | M9: GB
B10: Pinakin_FrontEnd | C10: Virtual Instance vCores 8 | RAM 32 GB | Disk Storage 512 GB | D10: 1 | E10: 9408 | F10: 5048 | G10: 9408 | H10: 5048 | J10: As per sizing received | K10: 8 | L10: 32 | M10: 512 | O10: =SUMPRODUCT(K10:M10,$O$7:$Q$7)*D10 -> 2824
B11: Pinakin_BackEnd | C11: Virtual Instance vCores 8 | RAM 32 GB | Disk Storage 512 GB | D11: 1 | E11: 9408 | F11: 5048 | G11: 9408 | H11: 5048 | J11: As per sizing received | K11: 8 | L11: 32 | M11: 512 | O11: =SUMPRODUCT(K11:M11,$O$7:$Q$7)*D11 -> 2824
B12: ML_Server | C12: Virtual Instance vCores 16 | RAM 64 GB | Disk Storage 512 GB | D12: 1 | E12: 14208 | F12: 8048 | G12: 14208 | H12: 8048 | J12: As per sizing received | K12: 16 | L12: 64 | M12: 512 | O12: =SUMPRODUCT(K12:M12,$O$7:$Q$7)*D12 -> 4624
B13: A.1 | C13: eNlight Cloud Hosting | D13: Unit | E13: Cost/Unit Per Month | F13: Discounted Cost/Unit Per Month | G13: MRC Cost | H13: Discounted MRC Cost | I13: OTC | J13: Comment
B14: Managed Services | C14: One Time Cost | D14: 1 | H14: 0 | I14: 1650
C15: Operating System Management Services | D15: 3 | E15: 1500 | F15: 550 | G15: 4500 | H15: 1650 | O15: =P15*D15 -> 1014.5082 | P15: 338.16939 | Q15: Windows OSMng Managed Services
C16: Storage Management | D16: 3 | E16: 550 | F16: 550 | G16: 1650 | H16: 1650 | O16: =P16*D16 -> 350.42036 | P16: 116.80679 | Q16: Managed Services Storage Management (TN) Mumbai Per TB NA
C17: ESDS' eMagic Monitoring for VMs & firewall & DB | D17: 3 | E17: 1000 | F17: 310 | G17: 3000 | H17: 930 | O17: =P17*D17 -> 900 | P17: 300 | Q17: eMagic Standard
B18: No. | C18: DESCRIPTION | G18: MRC Cost | H18: Discounted MRC Cost | I18: OTC
B19: 1 | C19: Infrastructure (A.1 ) | G19: 33024 | H19: 18144 | O19: =SUM(O10:O12) -> 10272
B20: 2 | C20: Managed Services (A.2) | G20: 9150 | H20: 4230 | O20: =SUM(O15:O17) -> 2264.9285
C21: Total Monthly Service Pay Without Taxes (A.1 + A.2 ) | G21: 42174 | H21: 22374 | I21: 1650 | O21: =SUM(O19:O20) -> 12536.929
C22: Total Yearly Service Pay Without Taxes (A.1 + A.2 ) | G22: 506088 | H22: 268488 | O22: =O21*12 -> 150443.14
C23: Total 5 year Service Pay Without Taxes (A.1 + A.2 ) | G23: 2530440 | H23: 1342440 | O23: =O22*5 -> 752215.71
E24: Discount percentage | G24: 46.9836
E25: Final MRC | G25: 1342440

Sheet Profitability
H2: Tenure | I2: 60
B8: Profitability Summary
C9: DC+DR
B10: Discount % | C10: At Present Discounted Price | E10: 0.1
B11: Particulars | C11: Amt ( in Rs) | D11: % | E11: Amt ( in Rs) | F11: %
B12: Selling Price
B13: OTC - IaaS | D13: =SUM(C13:C16)/C22 -> 0.81094127 | E13: =C13 -> 0 | F13: =SUM(E13:E16)/E22 -> 0.81094127 | G13: IaaS
B14: Server | C14: =SUM(Sheet1!H10:H12)*I2 -> 1088640 | E14: =($C$14*(100%-E10)) -> 979776 | G14: IaaS
B15: Storage | E15: =($C$15*(100%-E10)) -> 0 | G15: IaaS
B16: Network | E16: =($C$16*(100%-E10)) -> 0 | G16: IaaS
B17: OTC - SaaS | D17: =SUM(C17:C19)/C22 -> 0 | F17: =SUM(E17:E19)/E22 -> 0
B18: Software | E18: =($C$18*(100%-E10)) -> 0 | G18: SaaS
B19: Security | E19: =($C$19*(100%-E10)) -> 0 | G19: SaaS
B20: OTC - MS | D20: =(C20+C21)/C22 -> 0.18905873 | F20: =(E20+E21)/E22 -> 0.18905873
B21: Managed Service | C21: =SUM(Sheet1!H15:H17)*I2 -> 253800 | E21: =($C$21*(100%-E10)) -> 228420 | G21: MS
A22: 0 | B22: Total Contract Value | C22: =SUM(C13,C17,C20)+(SUM(C14,C15,C16,C18,C19,C21)-(SUM(C14,C15,C16,C18,C19,C21)*A22)) -> 1342440 | E22: =SUM(E13:E21) -> 1208196
B23: Input Cost
B24: Direct Overheads -20% of Input cost of Server | C24: =C43*20% -> 123264 | E24: =E43*20% -> 123264
B25: Direct Overheads -10% of Input cost of Storage | C25: =C44*10% -> 0 | E25: =E44*10% -> 0
B26: Network | E26: =C26 -> 0
B27: Software | E27: =C27 -> 0
B28: Security | E28: =C28 -> 0 | H28: =SUM(C26:C29,C43:C44) -> 752215.71
B29: Managed Service | C29: =SUM(Sheet1!O15:O17)*I2 -> 135895.71 | E29: =C29 -> 135895.71
A30: 0 | B30: CPC
B31: Total Input Cost | C31: =SUM(C24:C30) -> 259159.71 | E31: =SUM(E24:E30) -> 259159.71
B32: Gross Profit / ( Loss ) | C32: =C22-C31 -> 1083280.3 | E32: =E22-E31 -> 949036.29
B33: Less: Cash Overheads | C33: =(C31+C41+C42)*D33 -> 263275.5 | D33: 0.35 | E33: =(E31+E41+E42)*F33 -> 263275.5 | F33: 0.35
B34: EBITDA | C34: =C32-C33 -> 820004.79 | D34: =C34/C22 -> 0.61083161 | E34: =E32-E33 -> 685760.79 | F34: =E34/E22 -> 0.56759068
B36: EBITDA IaaS % | C36: =(((C14+C15+C13+C16)-(C26+C24+C25)*(1+D33))-(C41+C42)*D33-(C30*(1+D33)*D13)) -> 749664 | D36: =C36/SUM(C13:C16) -> 0.68862434 | E36: =(((E14+E15+E13+E16)-(E26+E24+E25)*(1+F33))-(E41+E42)*F33-(E30*(1+F33)*F13)) -> 640800 | F36: =E36/SUM(E13:E16) -> 0.65402704
B37: EBITDA SaaS % | C37: =(((C18+C19)-(C27+C28)*(1+D33)-(C30*(1+D33)*D17))) -> 0 | D37: =IFERROR(C37/(C18+C19),0) -> 0 | E37: =(((E18+E19)-(E27+E28)*(1+F33)-(E30*(1+F33)*F17))) -> 0 | F37: =IFERROR(E37/(E18+E19),0) -> 0
B38: EBITDA MS % | C38: =((C21-C29*(1+D33)-(C30*(1+D33)*D20))) -> 70340.79 | D38: =C38/C21 -> 0.27715047 | E38: =((E21-E29*(1+F33)-(E30*(1+F33)*F20))) -> 44960.79 | F38: =E38/E21 -> 0.19683386
B40: Less : Interest (Delay in Payment @12%) | C40: =IF('cash flow'!BK34<0,'cash flow'!BK34,0) -> 0 | E40: =((E22)*$A$40/365*12%) -> 0
B41: Less: 80% Depreciation Server | C41: =C43*80% -> 493056 | E41: =E43*80% -> 493056
B42: Less 90% Depreciation Storage | C42: =C44*90% -> 0 | E42: =E44*90% -> 0
B43: Infrastructure | C43: =SUM(Sheet1!O10:O12)*I2 -> 616320 | E43: =C43 -> 616320
B44: storage | E44: =C44 -> 0
B45: Total Depreciation | C45: =SUM(C41+C42) -> 493056 | E45: =SUM(E41+E42) -> 493056
B46: Net Profit for Total contract period (1yr) | C46: =C34-C40-C41-C42 -> 326948.79 | E46: =E34-E40-E41-E42 -> 192704.79
B47: Net Profit per Annum | C47: =C46 -> 326948.79 | D47: =C46/C22 -> 0.24354816 | E47: =E46 -> 192704.79 | F47: =E46/E22 -> 0.15949795
B49: Net Profit
...

Sheet cash flow
C3: -1
B4: Cash Flow | C4: 45748 | D4: 45778 | E4: 45809 | F4: 45839 | G4: 45870 | H4: 45901 | I4: 45931 | J4: 45962 | K4: 45992 | L4: 46023 | M4: 46054 | N4: 46082 | O4: Total
B5: Cash Inflow
B6: Revenue - Recurring | C6: =Profitability!C22/12 -> 111870 | D6: =C6 -> 111870 | E6: =D6 -> 111870 | F6: =E6 -> 111870 | G6: =F6 -> 111870 | H6: =G6 -> 111870 | I6: =H6 -> 111870 | J6: =I6 -> 111870 | K6: =J6 -> 111870 | ... N6: =M6 -> 111870 | O6: =SUM(C6:N6) -> 1342440
B7: Revenue - OTC | D7: 0 | E7: 0 | F7: 0 | G7: 0 | H7: 0 | I7: 0 | J7: 0 | K7: 0 | L7: 0 | O7: =SUM(C7:N7) -> 0
B8: Cash Outflow | O8: =SUM(O6:O7) -> 1342440
B9: Initial | C9: =-Profitability!C45 -> -493056 | O9: =SUM(C9:N9) -> -493056
B10: Recurring | C10: =-Profitability!C31/12 -> -21596.643 | D10: =C10 -> -21596.643 | E10: =D10 -> -21596.643 | F10: =E10 -> -21596.643 | G10: =F10 -> -21596.643 | H10: =G10 -> -21596.643 | I10: =H10 -> -21596.643 | J10: =I10 -> -21596.643 | K10: =J10 -> -21596.643 | ... N10: =M10 -> -21596.643 | O10: =SUM(C10:N10) -> -259159.71
B11: Overheads | C11: =-Profitability!C33/12 -> -21939.625 | D11: =C11 -> -21939.625 | E11: =D11 -> -21939.625 | F11: =E11 -> -21939.625 | G11: =F11 -> -21939.625 | H11: =G11 -> -21939.625 | I11: =H11 -> -21939.625 | J11: =I11 -> -21939.625 | K11: =J11 -> -21939.625 | ... N11: =M11 -> -21939.625 | O11: =SUM(C11:N11) -> -263275.5
B13: NET INFLOW/OUTFLOW | C13: =SUM(C6:C7,C9:C12) -> -424722.27 | D13: =SUM(D6:D7,D9:D12) -> 68333.733 | E13: =SUM(E6:E7,E9:E12) -> 68333.733 | F13: =SUM(F6:F7,F9:F12) -> 68333.733 | G13: =SUM(G6:G7,G9:G12) -> 68333.733 | H13: =SUM(H6:H7,H9:H12) -> 68333.733 | I13: =SUM(I6:I7,I9:I12) -> 68333.733 | J13: =SUM(J6:J7,J9:J12) -> 68333.733 | ... N13: =SUM(N6:N7,N9:N12) -> 68333.733 | O13: =SUM(C13:N13) -> 326948.79
B14: CUMULATIVE CASHFLOW | C14: =C13 -> -424722.27 | D14: =D13+C14 -> -356388.53 | E14: =E13+D14 -> -288054.8 | F14: =F13+E14 -> -219721.07 | G14: =G13+F14 -> -151387.34 | H14: =H13+G14 -> -83053.605 | I14: =I13+H14 -> -14719.872 | J14: =J13+I14 -> 53613.86 | K14: =K13+J14 -> 121947.59 | ... N14: =N13+M14 -> 326948.79
B16: Interest | C16: =C14*1% -> -4247.2227 | D16: =D14*1% -> -3563.8853 | E16: =E14*1% -> -2880.548 | F16: =F14*1% -> -2197.2107 | G16: =G14*1% -> -1513.8734 | H16: =H14*1% -> -830.53605 | I16: =I14*1% -> -147.19872 | J16: =J14*1% -> 536.1386 | ... N16: =N14*1% -> 3269.4879 | O16: =SUM(C16:N16) -> -5866.4086
B20: For 60 Months
B22: Cash Flow | C22: 1 | D22: =C22+1 -> 2 | E22: =D22+1 -> 3 | F22: =E22+1 -> 4 | G22: =F22+1 -> 5 | H22: =G22+1 -> 6 | I22: =H22+1 -> 7 | J22: =I22+1 -> 8 | K22: =J22+1 -> 9 | ... BJ22: =BI22+1 -> 60 | BK22: Total
B23: Cash Inflow
B24: Revenue - Recurring | C24: =Profitability!C22/Profitability!I2 -> 22374 | D24: =C24 -> 22374 | E24: =D24 -> 22374 | F24: =E24 -> 22374 | G24: =F24 -> 22374 | H24: =G24 -> 22374 | I24: =H24 -> 22374 | J24: =I24 -> 22374 | K24: =J24 -> 22374 | ... BJ24: =BI24 -> 22374 | BK24: =SUM(C24:BJ24) -> 1342440
B25: Revenue - OTC | D25: 0 | E25: 0 | F25: 0 | G25: 0 | H25: 0 | I25: 0 | J25: 0 | K25: 0 | L25: 0 | O25: ='[1]Primary Site - Production'!S71 -> 0 | P25: 0 | Q25: 0 | R25: 0 | S25: 0 | T25: 0 | U25: 0 | V25: 0 | W25: 0 | X25: 0 | AA25: ='[1]Primary Site - Production'!AE71 -> 0 | AB25: 0 | AC25: 0 | AD25: 0 | AE25: 0 | AF25: 0 | AG25: 0 | AH25: 0 | AI25: 0 | AJ25: 0 | AN25: ='[1]Primary Site - Production'!AR71 -> 0 | AO25: 0 | AP25: 0 | AQ25: 0 | AR25: 0 | AS25: 0 | AT25: 0 | AU25: 0 | AV25: 0 | AW25: 0 | AZ25: ='[1]Primary Site - Production'!BD71 -> 0 | BA25: 0 | BB25: 0 | BC25: 0 | BD25: 0 | BE25: 0 | BF25: 0 | BG25: 0 | BH25: 0 | BI25: 0 | BK25: =SUM(C25:BJ25) -> 0
B26: Cash Outflow
B27: Initial | C27: =-Profitability!C45 -> -493056 | O27: =-SUM([1]PnL!O59:O60) -> 0 | AA27: =-SUM([1]PnL!AA59:AA60) -> 0 | AN27: =-SUM([1]PnL!AN59:AN60) -> 0 | AZ27: =-SUM([1]PnL!AZ59:AZ60) -> 0 | BK27: =SUM(C27:BJ27) -> -493056
B28: Recurring | C28: =-Profitability!C31/Profitability!I2 -> -4319.3285 | D28: =C28 -> -4319.3285 | E28: =D28 -> -4319.3285 | F28: =E28 -> -4319.3285 | G28: =F28 -> -4319.3285 | H28: =G28 -> -4319.3285 | I28: =H28 -> -4319.3285 | J28: =I28 -> -4319.3285 | K28: =J28 -> -4319.3285 | ... BJ28: =BI28 -> -4319.3285 | BK28: =SUM(C28:BJ28) -> -259159.71
B29: Overheads | C29: =-Profitability!C33/Profitability!I2 -> -4387.925 | D29: =C29 -> -4387.925 | E29: =D29 -> -4387.925 | F29: =E29 -> -4387.925 | G29: =F29 -> -4387.925 | H29: =G29 -> -4387.925 | I29: =H29 -> -4387.925 | J29: =I29 -> -4387.925 | K29: =J29 -> -4387.925 | ... BJ29: =BI29 -> -4387.925 | BK29: =SUM(C29:BJ29) -> -263275.5
B31: NET INFLOW/OUTFLOW | C31: =SUM(C24:C25,C27:C30) -> -479389.25 | D31: =SUM(D24:D25,D27:D30) -> 13666.747 | E31: =SUM(E24:E25,E27:E30) -> 13666.747 | F31: =SUM(F24:F25,F27:F30) -> 13666.747 | G31: =SUM(G24:G25,G27:G30) -> 13666.747 | H31: =SUM(H24:H25,H27:H30) -> 13666.747 | I31: =SUM(I24:I25,I27:I30) -> 13666.747 | J31: =SUM(J24:J25,J27:J30) -> 13666.747 | ... BK31: =SUM(BK24:BK25,BK27:BK30) -> 326948.79
B32: CUMULATIVE CASHFLOW | C32: =C31 -> -479389.25 | D32: =D31+C32 -> -465722.51 | E32: =E31+D32 -> -452055.76 | F32: =F31+E32 -> -438389.01 | G32: =G31+F32 -> -424722.27 | H32: =H31+G32 -> -411055.52 | I32: =I31+H32 -> -397388.77 | J32: =J31+I32 -> -383722.03 | K32: =K31+J32 -> -370055.28 | ... BK32: =BK31+BJ32 -> 653897.58
B34: Interest | C34: =C32*1% -> -4793.8925 | D34: =D32*1% -> -4657.2251 | E34: =E32*1% -> -4520.5576 | F34: =F32*1% -> -4383.8901 | G34: =G32*1% -> -4247.2227 | H34: =H32*1% -> -4110.5552 | I34: =I32*1% -> -3973.8877 | J34: =J32*1% -> -3837.2203 | ... BK34: =BK32*1% -> 6538.9758
