Workbook

Sheet Doc Version
B6: Customer Name : | C6: Intellect Design Arena
B7: Partner Name : | C7: NA
B8: Date : | C8: 45867
B9: Opp_ID :
B10: Solution : | C10: ESDS Dedicated server Hosting
B11: Contract term : | C11: 3 years
B13: Date | C13: Doc Version | D13: Account Manager | E13: Solution Architect | F13: Reviewed By
B14: 45867 | C14: V1.0 | D14: Rajesh | E14: Jeevan

Sheet Summary Sheet
G1: Customer Name : | H1: Intellect Design Arena
G2: Partner Name : | H2: NA
G3: Date : | H3: 45867
G4: Opp_ID :
G5: Contract term : | H5: 3 Year
B6: Service Components | D6: Monthly Service Pay | E6: OTC | F6: Yearly Service Pay
B7: ESDS Dedicated Server Hosting & Managed Services
B8: ESDS' Dedicated Hosting Services ->DC site | D8: =BoM!F21 -> 262858.03 | E8: =BoM!H23 -> 157714.82 | F8: =D8*12 -> 3154296.3
B9: ESDS' Managed Services ->DC site | D9: =BoM!F22 -> 19000 | E9: - | F9: =D9*12 -> 228000
B10: Total for Dedicated Server Hosting & Managed Services | D10: =SUM(D8:D9) -> 281858.03 | E10: {=E8:E9} -> 157714.82 | F10: =SUM(F8:F9) -> 3382296.3
E11: -
B13: * For detail Terms & conditions, please refer to our standard terms & conditions document.
B14: * Any component/Service not mentioned in the BOM/Main Commercials is out of ESDS's Scope.
B15: * The quote is valid for 15 days from the date of submission of offer.
B17: Terms & Conditions
B18: Price:
B19: • All prices are in Indian Rupee without Taxes.
B20: • Any change in the taxes, duties or levies due to change in government policies will be borne by the customer.
B21: • Billing shall start from the date of infrastructure hand-over in partial or full, irrespective of the Go-Live of the project, for e.g Dev environment is setup and released to client/partner for development activity, then the billing for the Dev enviornment will start immediately after Development environment is handed over to department / partner, similarly for any other environment, what ever is handed over, billing will start immediately after that.
B22: • The quote is valid for 15 days from the date of submission of offer.
B23: • Above best prices are for the minimum commitment of 36 months.
B24: • Prices are composite for the total Bill of Material and may vary with change in the Bill of Material due to increase or decrease in quantity/service period at the time of ordering.
B25: • One time Infra setup cost is for setting up the infra environment for the one time as per final BOM/PO. In case the setup has to be re-done or any setup modifications are required later, it will be charged extra at actuals.
... B55: • In case of any disputes at the time of PO acceptance or during contract period related to any requirement not covered in the proposal / BoM / BoQ submitted by ESDS, both parties that is Client & ESDS will mutually discuss and check the requirement and come to conclusion to proceed further & how, further to this, in case there is dispute due to any such additional/new/change requirement for which there’s commercial impact, client should not hold the project implementation/completion and payments to ESDS.

Sheet BoM
B2: Sr. No. | D2: Qty | E2: Unit Rate | F2: Total Monthly Service Pay | H2: Total one time Service Pay | I2: Comments
B3: 1 | C3: Dedicated Setup
B4: Physical | C4: Processor – Intel Xeon Gold Core – 20 RAM – 512 GB Storage – 1800 GB | D4: 3 | E4: ='CAPEX - OPEX'!N4 -> 30395.343 | F4: =D4*E4 -> 91186.028 | K4: ='CAPEX - OPEX'!G4+'CAPEX - OPEX'!L4 -> 27601.274 | L4: =K4*D4 -> 82803.823
B5: 2 | C5: Software & OS
B6: 2.1 | C6: Hypervisor, OS, DB, App licenses | D6: Client scope | E6: 0 | F6: 0
B7: 3 | C7: Network & Storage Service
B8: 3.1 | C8: Volume Based-Internet Bandwidth | D8: 500 | E8: 6 | F8: =D8*E8 -> 3000 | I8: As per inputs | K8: 2 | L8: =K8*D8 -> 1000
B9: 3.2 | C9: Public IP's | D9: 3 | E9: 900 | F9: =E9*D9 -> 2700 | I9: As per inputs | K9: 500 | L9: =K9*D9 -> 1500
B10: 3.3 | C10: Cross-connect for existing FW and Servers | D10: 6 | E10: 1500 | F10: =E10*D10 -> 9000 | K10: 500 | L10: =K10*D10 -> 3000
B11: 3.4 | C11: shared switchports -1Gig | D11: 3 | E11: 2000 | F11: =E11*D11 -> 6000 | K11: 1000 | L11: =K11*D11 -> 3000
B12: 3.5 | C12: shared switchports -10Gig | D12: 6 | E12: 3000 | F12: =E12*D12 -> 18000 | K12: 1500 | L12: =K12*D12 -> 9000
B13: 3.6 | C13: Performance Storage on Cloud (3000 IOPs/TB) | D13: 13108 | E13: 9 | F13: =E13*D13 -> 117972 | I13: As per inputs | K13: 1.9214638 | L13: =K13*D13 -> 25186.548
B14: 4 | C14: Security & Backup Services
B15: 4.1 | C15: vFirewall (25 SSLVPN + 2 site to site VPN Tunnel) | D15: 1 | E15: 15000 | F15: =D15*E15 -> 15000 | K15: 5608.6154 | L15: =K15*D15 -> 5608.6154
B16: 5 | C16: Hosting Services
B17: 5.1 | C17: One Time Infrastructure setup as per ESDS' standard SOW | D17: 1 | E17: =SUM(F4:F15)*12*5% -> 157714.82 | L17: =K17*D17 -> 0
B18: 5.2 | C18: Storage Mgt as per ESDS' standard SOW | D18: 13 | E18: 500 | F18: =E18*D18 -> 6500 | K18: 116.80679 | L18: =K18*D18 -> 1518.4882
B19: 5.3 | C19: Firewall Mgt as per ESDS' standard SOW | D19: 1 | E19: 8500 | F19: =E19*D19 -> 8500 | K19: 5079.93 | L19: =K19*D19 -> 5079.93
B20: 5.4 | C20: Basic Infra Monitoring for VMs as per ESDS' standard SOW | D20: 4 | E20: 1000 | F20: =E20*D20 -> 4000 | K20: 500 | L20: =K20*D20 -> 2000
C21: Total Charges for Hosting Infrastructure (A) | F21: =SUM(F4:F15) -> 262858.03 | L21: =SUM(L4:L15) -> 131098.99
C22: Total Charges for Managed Services (B) | F22: =SUM(F18:F20) -> 19000 | L22: =SUM(L18:L20) -> 8598.4182
C23: Total Pay without Taxes (A+B) | F23: =F22+F21 -> 281858.03 | H23: =E17 -> 157714.82 | L23: =L22+L21 -> 139697.4

Sheet Profitability
J2: Tenure | K2: 36
W4: 1.7932131
B8: Profitability Summary
B10: MRC | C10: =(SUM(C16:C23)-C19)/K2 -> 281858.03 | E10: =(SUM(E16:E23)-E19)/K2 -> 253672.23 | G10: =(SUM(G16:G23)-G19)/K2 -> 239579.32
B11: OTC | C11: =(C10-(C23/K2))*12*5% -> 157714.82 | E11: =(E10-(E23/K2))*12*5% -> 141943.34 | G11: =(G10-(G23/K2))*12*5% -> 134057.59
B12: Discount % | C12: Present Price | E12: 0.1 | G12: 0.15
B13: Particulars | C13: Amt ( in Rs) | D13: % | E13: Amt ( in Rs) | F13: % | G13: Amt ( in Rs) | H13: %
B14: Selling Price
B15: OTC - IaaS | C15: =BoM!E17 -> 157714.82 | D15: =SUM(C15:C18)/C24 -> 0.88121814 | E15: =E11 -> 141943.34 | F15: =SUM(E15:E18)/E24 -> 0.88121814 | G15: =G11 -> 134057.59 | H15: =SUM(G15:G18)/G24 -> 0.88121814 | I15: IaaS
B16: Server | C16: =SUM(BoM!F4)*K2 -> 3282697 | E16: =C16*(100%-$E$12) -> 2954427.3 | G16: =C16*(100%-$G$12) -> 2790292.5 | I16: IaaS
B17: Storage | C17: =SUM(BoM!F13)*K2 -> 4246992 | E17: =C17*(100%-$E$12) -> 3822292.8 | G17: =C17*(100%-$G$12) -> 3609943.2 | I17: IaaS
B18: Network | C18: =SUM(BoM!F8:F12)*K2 -> 1393200 | E18: =C18*(100%-$E$12) -> 1253880 | G18: =C18*(100%-$G$12) -> 1184220 | I18: IaaS
B19: OTC - SaaS | D19: =SUM(C19:C21)/C24 -> 0.052403761 | F19: =SUM(E19:E21)/E24 -> 0.052403761 | G19: =C19*(100%-$G$12) -> 0 | H19: =SUM(G19:G21)/G24 -> 0.052403761
B20: Software | C20: =SUM(BoM!F6) -> 0 | E20: =C20*(100%-$E$12) -> 0 | G20: =C20*(100%-$G$12) -> 0 | I20: SaaS
B21: Security | C21: =SUM(BoM!F15)*K2 -> 540000 | E21: =C21*(100%-$E$12) -> 486000 | G21: =C21*(100%-$G$12) -> 459000 | I21: SaaS
B22: OTC - MS | D22: =(C22+C23)/C24 -> 0.066378098 | E22: =C22*(100%-$E$12) -> 0 | F22: =(E22+E23)/E24 -> 0.066378098 | G22: =C22*(100%-$G$12) -> 0 | H22: =(G22+G23)/G24 -> 0.066378098
B23: Managed Service | C23: =SUM(BoM!F18:F20)*K2 -> 684000 | E23: =C23*(100%-$E$12) -> 615600 | G23: =C23*(100%-$G$12) -> 581400 | I23: MS
A24: 0 | B24: Total Contract Value | C24: =SUM(C15,C19,C22)+(SUM(C16,C17,C18,C20,C21,C23)-(SUM(C16,C17,C18,C20,C21,C23)*A24)) -> 10304604 | E24: =SUM(E15:E23) -> 9274143.5 | G24: =SUM(G15:G23) -> 8758913.3 | K24: CPC : Not Consider
B25: Input Cost
B26: Direct Overheads -20% of Input cost of Server | C26: =C46*20% -> 596187.52 | E26: =E46*20% -> 596187.52 | G26: =G46*20% -> 596187.52
B27: Direct Overheads -10% of Input cost of Storage | C27: =C47*10% -> 90671.572 | E27: =E47*10% -> 90671.572 | G27: =G47*10% -> 90671.572
B28: Network | C28: =SUM(BoM!L8:L12)*K2 -> 630000 | E28: =C28 -> 630000 | G28: =E28 -> 630000
B29: Software | C29: =SUM(BoM!L6)*K2 -> 0 | E29: =C29 -> 0 | G29: =E29 -> 0
B30: Security | C30: =SUM(BoM!L15)*K2 -> 201910.15 | E30: =C30 -> 201910.15 | G30: =E30 -> 201910.15 | J30: =SUM(C28:C31,C46:C47) -> 5029106.5
B31: Managed Service | C31: =SUM(BoM!L18:L20)*K2 -> 309543.06 | E31: =C31 -> 309543.06 | G31: =E31 -> 309543.06
A32: 0 | B32: CPC | C32: =(C24-C15)*$A$32 -> 0 | E32: =(E24-E15)*$A$32 -> 0 | G32: =(G24-G15)*$A$32 -> 0
B33: Total Input Cost | C33: =SUM(C26:C32) -> 1828312.3 | E33: =SUM(E26:E32) -> 1828312.3 | G33: =SUM(G26:G32) -> 1828312.3
B34: Gross Profit / ( Loss ) | C34: =C24-C33 -> 8476291.5 | E34: =E24-E33 -> 7445831.1 | G34: =G24-G33 -> 6930601
B35: Less: Cash Overheads | C35: =(C33+C44+C45-C32)*D35 -> 1760187.3 | D35: 0.35 | E35: =(E33+E44+E45-E32)*F35 -> 1760187.3 | F35: 0.35 | G35: =(G33+G44+G45-G32)*H35 -> 1760187.3 | H35: 0.35
B36: EBITDA | C36: =C34-C35 -> 6716104.2 | D36: =C36/C24 -> 0.65175764 | E36: =E34-E35 -> 5685643.9 | F36: =E36/E24 -> 0.61306404 | G36: =G34-G35 -> 5170413.7 | H36: =G36/G24 -> 0.5903031
B38: EBITDA IaaS % | C38: =(((C16+C17+C15+C18)-(C28+C26+C27)*(1+D35))-(C44+C45)*D35-(C32*(1+D35)*D15)) -> 6182566.1 | D38: =C38/SUM(C15:C18) -> 0.68085407 | E38: =(((E16+E17+E15+E18)-(E28+E26+E27)*(1+F35))-(E44+E45)*F35-(E32*(1+F35)*F15)) -> 5274505.7 | F38: =E38/SUM(E15:E18) -> 0.64539341 | G38: =(((G16+G17+G15+G18)-(G28+G26+G27)*(1+H35))-(G44+G45)*H35-(G32*(1+H35)*H15)) -> 4820475.5 | H38: =G38/SUM(G15:G18) -> 0.6245342
B39: EBITDA SaaS % | C39: =(((C20+C21)-(C29+C30)*(1+D35)-(C32*(1+D35)*D19))) -> 267421.29 | D39: =IFERROR(C39/(C20+C21),0) -> 0.49522462 | E39: =(((E20+E21)-(E29+E30)*(1+F35)-(E32*(1+F35)*F19))) -> 213421.29 | F39: =IFERROR(E39/(E20+E21),0) -> 0.43913846 | G39: =(((G20+G21)-(G29+G30)*(1+H35)-(G32*(1+H35)*H19))) -> 186421.29 | H39: =IFERROR(G39/(G20+G21),0) -> 0.40614661
B40: EBITDA MS % | C40: =((C23-C31*(1+D35)-(C32*(1+D35)*D22))) -> 266116.87 | D40: =C40/C23 -> 0.38905976 | E40: =((E23-E31*(1+F35)-(E32*(1+F35)*F22))) -> 197716.87 | F40: =E40/E23 -> 0.32117751 | G40: =((G23-G31*(1+H35)-(G32*(1+H35)*H22))) -> 163516.87 | H40: =G40/G23 -> 0.28124677
B42: Less : Interest (Delay in Payment @12%) | C42: =-IF('Cash Flow'!AM17<0,'Cash Flow'!AM17,0) -> 0 | E42: =-IF('Cash Flow'!AM34<0,'Cash Flow'!AM34,0) -> 69923.995 | G42: =-IF('Cash Flow'!AM52<0,'Cash Flow'!AM52,0) -> 163782.72
A43: 30 | B43: Finance charge late fee payment | C43: =(C24-C15-C19-C22)*$A43/365*4% -> 33359.635 | E43: =(C24-C15-C19-C22)*$A43/365*4% -> 33359.635 | G43: =(C24-C15-C19-C22)*$A43/365*4% -> 33359.635 | K43: Payment Terms: monthly advance within 30 days
B44: Less: 80% Depreciation Server | C44: =C46*80% -> 2384750.1 | E44: =E46*80% -> 2384750.1 | G44: =G46*80% -> 2384750.1
B45: Less 90% Depreciation Storage | C45: =C47*90% -> 816044.15 | E45: =E47*90% -> 816044.15 | G45: =G47*90% -> 816044.15
B46: Infrastructure | C46: =SUM(BoM!L4)*K2 -> 2980937.6 | E46: =C46 -> 2980937.6 | G46: =E46 -> 2980937.6
B47: storage | C47: =SUM(BoM!L13)*K2 -> 906715.72 | E47: =C47 -> 906715.72 | G47: =E47 -> 906715.72
B48: Total Depreciation | C48: =SUM(C44+C45) -> 3200794.2 | E48: =SUM(E44+E45) -> 3200794.2 | G48: =SUM(G44+G45) -> 3200794.2
...

Sheet Cash Flow
B3: For 36 Months
B5: Cash Flow | C5: 1 | D5: =C5+1 -> 2 | E5: =D5+1 -> 3 | F5: =E5+1 -> 4 | G5: =F5+1 -> 5 | H5: =G5+1 -> 6 | I5: =H5+1 -> 7 | J5: =I5+1 -> 8 | K5: =J5+1 -> 9 | ... AL5: =AK5+1 -> 36 | AM5: Total
B6: Cash Inflow
B7: Revenue - Recurring | C7: =(Profitability!C24-Profitability!C11)/Profitability!K2 -> 281858.03 | D7: =C7 -> 281858.03 | E7: =D7 -> 281858.03 | F7: =E7 -> 281858.03 | G7: =F7 -> 281858.03 | H7: =G7 -> 281858.03 | I7: =H7 -> 281858.03 | J7: =I7 -> 281858.03 | K7: =J7 -> 281858.03 | ... AL7: =AK7 -> 281858.03 | AM7: =SUM(C7:AL7) -> 10146889
B8: Revenue - OTC | C8: =Profitability!C15 -> 157714.82 | D8: 0 | E8: 0 | F8: 0 | G8: 0 | H8: 0 | I8: 0 | J8: 0 | K8: 0 | L8: 0 | M8: 0 | N8: 0 | O8: 0 | P8: 0 | Q8: 0 | R8: 0 | S8: 0 | T8: 0 | U8: 0 | V8: 0 | W8: 0 | X8: 0 | Y8: 0 | Z8: 0 | AA8: 0 | AB8: 0 | AC8: 0 | AD8: 0 | AE8: 0 | AF8: 0 | AG8: 0 | AH8: 0 | AI8: 0 | AJ8: 0 | AK8: 0 | AL8: 0 | AM8: =SUM(C8:AL8) -> 157714.82
B9: Cash Outflow
B10: Initial | C10: =-Profitability!C48 -> -3200794.2 | D10: 0 | E10: 0 | F10: 0 | G10: 0 | H10: 0 | I10: 0 | J10: 0 | K10: 0 | L10: 0 | M10: 0 | N10: 0 | O10: 0 | P10: 0 | Q10: 0 | R10: 0 | S10: 0 | T10: 0 | U10: 0 | V10: 0 | W10: 0 | X10: 0 | Y10: 0 | Z10: 0 | AA10: 0 | AB10: 0 | AC10: 0 | AD10: 0 | AE10: 0 | AF10: 0 | AG10: 0 | AH10: 0 | AI10: 0 | AJ10: 0 | AK10: 0 | AL10: 0 | AM10: =SUM(C10:AL10) -> -3200794.2
B11: Recurring | C11: =-Profitability!C33/Profitability!K2 -> -50786.453 | D11: =C11 -> -50786.453 | E11: =D11 -> -50786.453 | F11: =E11 -> -50786.453 | G11: =F11 -> -50786.453 | H11: =G11 -> -50786.453 | I11: =H11 -> -50786.453 | J11: =I11 -> -50786.453 | K11: =J11 -> -50786.453 | ... AL11: =AK11 -> -50786.453 | AM11: =SUM(C11:AL11) -> -1828312.3
B12: Overheads | C12: =-Profitability!C35/Profitability!K2 -> -48894.091 | D12: =C12 -> -48894.091 | E12: =D12 -> -48894.091 | F12: =E12 -> -48894.091 | G12: =F12 -> -48894.091 | H12: =G12 -> -48894.091 | I12: =H12 -> -48894.091 | J12: =I12 -> -48894.091 | K12: =J12 -> -48894.091 | ... AL12: =AK12 -> -48894.091 | AM12: =SUM(C12:AL12) -> -1760187.3
B14: NET INFLOW/OUTFLOW | C14: =SUM(C7:C8,C10:C13) -> -2860901.9 | D14: =SUM(D7:D8,D10:D13) -> 182177.48 | E14: =SUM(E7:E8,E10:E13) -> 182177.48 | F14: =SUM(F7:F8,F10:F13) -> 182177.48 | G14: =SUM(G7:G8,G10:G13) -> 182177.48 | H14: =SUM(H7:H8,H10:H13) -> 182177.48 | I14: =SUM(I7:I8,I10:I13) -> 182177.48 | J14: =SUM(J7:J8,J10:J13) -> 182177.48 | ... AL14: =SUM(AL7:AL8,AL10:AL13) -> 182177.48 | AM14: =SUM(C14:AL14) -> 3515310
B15: CUMULATIVE CASHFLOW | C15: =C14 -> -2860901.9 | D15: =D14+C15 -> -2678724.5 | E15: =E14+D15 -> -2496547 | F15: =F14+E15 -> -2314369.5 | G15: =G14+F15 -> -2132192 | H15: =H14+G15 -> -1950014.5 | I15: =I14+H15 -> -1767837 | J15: =J14+I15 -> -1585659.5 | K15: =K14+J15 -> -1403482.1 | ... AL15: =AL14+AK15 -> 3515310
B17: Interest | C17: =C15*1% -> -28609.019 | D17: =D15*1% -> -26787.245 | E17: =E15*1% -> -24965.47 | F17: =F15*1% -> -23143.695 | G17: =G15*1% -> -21321.92 | H17: =H15*1% -> -19500.145 | I17: =I15*1% -> -17678.37 | J17: =J15*1% -> -15856.595 | ... AL17: =AL15*1% -> 35153.1 | AM17: =SUM(C17:AL17) -> 117793.45
AM19: =AM14-Profitability!C43 -> 3481950.4
B20: For 24 Months
B22: Cash Flow | C22: 1 | D22: =C22+1 -> 2 | E22: =D22+1 -> 3 | F22: =E22+1 -> 4 | G22: =F22+1 -> 5 | H22: =G22+1 -> 6 | I22: =H22+1 -> 7 | J22: =I22+1 -> 8 | K22: =J22+1 -> 9 | ... AL22: =AK22+1 -> 36 | AM22: Total
B23: Cash Inflow
B24: Revenue - Recurring | C24: =(Profitability!E24-Profitability!E11)/Profitability!K2 -> 253672.23 | D24: =C24 -> 253672.23 | E24: =D24 -> 253672.23 | F24: =E24 -> 253672.23 | G24: =F24 -> 253672.23 | H24: =G24 -> 253672.23 | I24: =H24 -> 253672.23 | J24: =I24 -> 253672.23 | K24: =J24 -> 253672.23 | ... AL24: =AK24 -> 253672.23 | AM24: =SUM(C24:AL24) -> 9132200.1
B25: Revenue - OTC | C25: =C8 -> 157714.82 | D25: 0 | E25: 0 | F25: 0 | G25: 0 | H25: 0 | I25: 0 | J25: 0 | K25: 0 | L25: 0 | M25: 0 | N25: 0 | O25: 0 | P25: 0 | Q25: 0 | R25: 0 | S25: 0 | T25: 0 | U25: 0 | V25: 0 | W25: 0 | X25: 0 | Y25: 0 | Z25: 0 | AA25: 0 | AB25: 0 | AC25: 0 | AD25: 0 | AE25: 0 | AF25: 0 | AG25: 0 | AH25: 0 | AI25: 0 | AJ25: 0 | AK25: 0 | AL25: 0 | AM25: =SUM(C25:AL25) -> 157714.82
B26: Cash Outflow
B27: Initial | C27: =-Profitability!E48 -> -3200794.2 | D27: 0 | E27: 0 | F27: 0 | G27: 0 | H27: 0 | I27: 0 | J27: 0 | K27: 0 | L27: 0 | M27: 0 | N27: 0 | O27: 0 | P27: 0 | Q27: 0 | R27: 0 | S27: 0 | T27: 0 | U27: 0 | V27: 0 | W27: 0 | X27: 0 | Y27: 0 | Z27: 0 | AA27: 0 | AB27: 0 | AC27: 0 | AD27: 0 | AE27: 0 | AF27: 0 | AG27: 0 | AH27: 0 | AI27: 0 | AJ27: 0 | AK27: 0 | AL27: 0 | AM27: =SUM(C27:AL27) -> -3200794.2
B28: Recurring | C28: =-Profitability!E33/Profitability!K2 -> -50786.453 | D28: =C28 -> -50786.453 | E28: =D28 -> -50786.453 | F28: =E28 -> -50786.453 | G28: =F28 -> -50786.453 | H28: =G28 -> -50786.453 | I28: =H28 -> -50786.453 | J28: =I28 -> -50786.453 | K28: =J28 -> -50786.453 | ... AL28: =AK28 -> -50786.453 | AM28: =SUM(C28:AL28) -> -1828312.3
B29: Overheads | C29: =-Profitability!E35/Profitability!K2 -> -48894.091 | D29: =C29 -> -48894.091 | E29: =D29 -> -48894.091 | F29: =E29 -> -48894.091 | G29: =F29 -> -48894.091 | H29: =G29 -> -48894.091 | I29: =H29 -> -48894.091 | J29: =I29 -> -48894.091 | K29: =J29 -> -48894.091 | ... AL29: =AK29 -> -48894.091 | AM29: =SUM(C29:AL29) -> -1760187.3
B31: NET INFLOW/OUTFLOW | C31: =SUM(C24:C25,C27:C30) -> -2889087.7 | D31: =SUM(D24:D25,D27:D30) -> 153991.68 | E31: =SUM(E24:E25,E27:E30) -> 153991.68 | F31: =SUM(F24:F25,F27:F30) -> 153991.68 | G31: =SUM(G24:G25,G27:G30) -> 153991.68 | H31: =SUM(H24:H25,H27:H30) -> 153991.68 | I31: =SUM(I24:I25,I27:I30) -> 153991.68 | J31: =SUM(J24:J25,J27:J30) -> 153991.68 | ... AL31: =SUM(AL24:AL25,AL27:AL30) -> 153991.68 | AM31: =SUM(C31:AL31) -> 2500621.1
B32: CUMULATIVE CASHFLOW | C32: =C31 -> -2889087.7 | D32: =D31+C32 -> -2735096.1 | E32: =E31+D32 -> -2581104.4 | F32: =F31+E32 -> -2427112.7 | G32: =G31+F32 -> -2273121 | H32: =H31+G32 -> -2119129.3 | I32: =I31+H32 -> -1965137.7 | J32: =J31+I32 -> -1811146 | K32: =K31+J32 -> -1657154.3 | ... AL32: =AL31+AK32 -> 2500621.1
B34: Interest | C34: =C32*1% -> -28890.877 | D34: =D32*1% -> -27350.961 | E34: =E32*1% -> -25811.044 | F34: =F32*1% -> -24271.127 | G34: =G32*1% -> -22731.21 | H34: =H32*1% -> -21191.293 | I34: =I32*1% -> -19651.377 | J34: =J32*1% -> -18111.46 | ... AL34: =AL32*1% -> 25006.211 | AM34: =SUM(C34:AL34) -> -69923.995
AM36: =AM31-Profitability!E43+AM34 -> 2397337.5
B38: For 12 Months
B40: Cash Flow | C40: 1 | D40: =C40+1 -> 2 | E40: =D40+1 -> 3 | F40: =E40+1 -> 4 | G40: =F40+1 -> 5 | H40: =G40+1 -> 6 | I40: =H40+1 -> 7 | J40: =I40+1 -> 8 | K40: =J40+1 -> 9 | ... AL40: =AK40+1 -> 36 | AM40: Total
B41: Cash Inflow
B42: Revenue - Recurring | C42: =(Profitability!G24-Profitability!G11)/Profitability!K2 -> 239579.32 | D42: =C42 -> 239579.32 | E42: =D42 -> 239579.32 | F42: =E42 -> 239579.32 | G42: =F42 -> 239579.32 | H42: =G42 -> 239579.32 | I42: =H42 -> 239579.32 | J42: =I42 -> 239579.32 | K42: =J42 -> 239579.32 | ... AL42: =AK42 -> 239579.32 | AM42: =SUM(C42:AL42) -> 8624855.7
B43: Revenue - OTC | C43: =C25 -> 157714.82 | D43: 0 | E43: 0 | F43: 0 | G43: 0 | H43: 0 | I43: 0 | J43: 0 | K43: 0 | L43: 0 | M43: 0 | N43: 0 | O43: 0 | P43: 0 | Q43: 0 | R43: 0 | S43: 0 | T43: 0 | U43: 0 | V43: 0 | W43: 0 | X43: 0 | Y43: 0 | Z43: 0 | AA43: 0 | AB43: 0 | AC43: 0 | AD43: 0 | AE43: 0 | AF43: 0 | AG43: 0 | AH43: 0 | AI43: 0 | AJ43: 0 | AK43: 0 | AL43: 0 | AM43: =SUM(C43:AL43) -> 157714.82
B44: Cash Outflow
B45: Initial | C45: =-Profitability!G48 -> -3200794.2 | D45: 0 | E45: 0 | F45: 0 | G45: 0 | H45: 0 | I45: 0 | J45: 0 | K45: 0 | L45: 0 | M45: 0 | N45: 0 | O45: 0 | P45: 0 | Q45: 0 | R45: 0 | S45: 0 | T45: 0 | U45: 0 | V45: 0 | W45: 0 | X45: 0 | Y45: 0 | Z45: 0 | AA45: 0 | AB45: 0 | AC45: 0 | AD45: 0 | AE45: 0 | AF45: 0 | AG45: 0 | AH45: 0 | AI45: 0 | AJ45: 0 | AK45: 0 | AL45: 0 | AM45: =SUM(C45:AL45) -> -3200794.2
B46: Recurring | C46: =-Profitability!G33/Profitability!K2 -> -50786.453 | D46: =C46 -> -50786.453 | E46: =D46 -> -50786.453 | F46: =E46 -> -50786.453 | G46: =F46 -> -50786.453 | H46: =G46 -> -50786.453 | I46: =H46 -> -50786.453 | J46: =I46 -> -50786.453 | K46: =J46 -> -50786.453 | ... AL46: =AK46 -> -50786.453 | AM46: =SUM(C46:AL46) -> -1828312.3
B47: Overheads | C47: =-Profitability!G35/Profitability!K2 -> -48894.091 | D47: =C47 -> -48894.091 | E47: =D47 -> -48894.091 | F47: =E47 -> -48894.091 | G47: =F47 -> -48894.091 | H47: =G47 -> -48894.091 | I47: =H47 -> -48894.091 | J47: =I47 -> -48894.091 | K47: =J47 -> -48894.091 | ... AL47: =AK47 -> -48894.091 | AM47: =SUM(C47:AL47) -> -1760187.3
B49: NET INFLOW/OUTFLOW | C49: =SUM(C42:C43,C45:C48) -> -2903180.6 | D49: =SUM(D42:D43,D45:D48) -> 139898.78 | E49: =SUM(E42:E43,E45:E48) -> 139898.78 | F49: =SUM(F42:F43,F45:F48) -> 139898.78 | G49: =SUM(G42:G43,G45:G48) -> 139898.78 | H49: =SUM(H42:H43,H45:H48) -> 139898.78 | I49: =SUM(I42:I43,I45:I48) -> 139898.78 | J49: =SUM(J42:J43,J45:J48) -> 139898.78 | ... AL49: =SUM(AL42:AL43,AL45:AL48) -> 139898.78 | AM49: =SUM(C49:AL49) -> 1993276.6
B50: CUMULATIVE CASHFLOW | C50: =C49 -> -2903180.6 | D50: =D49+C50 -> -2763281.9 | E50: =E49+D50 -> -2623383.1 | F50: =F49+E50 -> -2483484.3 | G50: =G49+F50 -> -2343585.5 | H50: =H49+G50 -> -2203686.7 | I50: =I49+H50 -> -2063788 | J50: =J49+I50 -> -1923889.2 | K50: =K49+J50 -> -1783990.4 | ... AL50: =AL49+AK50 -> 1993276.6
B52: Interest | C52: =C50*1% -> -29031.806 | D52: =D50*1% -> -27632.819 | E52: =E50*1% -> -26233.831 | F52: =F50*1% -> -24834.843 | G52: =G50*1% -> -23435.855 | H52: =H50*1% -> -22036.867 | I52: =I50*1% -> -20637.88 | J52: =J50*1% -> -19238.892 | ... AL52: =AL50*1% -> 19932.766 | AM52: =SUM(C52:AL52) -> -163782.72
AM54: =AM52+AM49-Profitability!G43 -> 1796134.3

Sheet CAPEX - OPEX
B1: Hardware - Capex to Opex | E1: contigency buffer | F1: ROI | I1: Racks | K1: Power | M1: Margin
E2: 0 | F2: 3 | G2: 0.13 | I2: 800 | K2: 12500 | M2: 0.2 | O2: 12
B3: Technology | C3: Description | D3: QTY | E3: Unit Cost | F3: Total Cost in INR | G3: COC | H3: Rack Space in U | I3: Rack Space | J3: PSU in Watt | K3: Colocation | L3: Total Colocation | M3: Selling Price/Unit | N3: Total Monthly Selling Price | O3: Total for contract Terms
B4: Physical Server Nodes - DC | C4: Processor – Intel Xeon Gold Core – 20 RAM – 512 GB Storage – 1800 GB | D4: 1 | E4: 950000 | F4: =D4*E4 -> 950000 | G4: =((E4*$G$2)/(1-(1+$G$2)^(-$F$2)))/36 -> 11176.274 | H4: 1 | I4: =H4*$I$2 -> 800 | J4: 1000 | K4: =(J4/800)*$K$2 -> 15625 | L4: =I4+K4 -> 16425 | M4: =(G4/(1-$M$2))+L4 -> 30395.343 | N4: =D4*M4 -> 30395.343 | O4: =N4*$O$2 -> 364744.11

Sheet RACI
B2: RACI Matrix : Dedicated Hosting
B3: Activity | C3: Client | D3: ESDS
B4: Infrastructure Setup (Virtual Instance/Physical instance) - DC | C4: I, C | D4: R, A
B5: Operating System Administration- DC | C5: R, A | D5: I,C
B6: Any Third Party Application/Database Licenses - DC | C6: R, A, C | D6: I
B7: vFirewall installation and configuration -DC | C7: I,C | D7: R,A
B8: Any Third Party Application/Database Installation, Configuration & Daily Management - DC | C8: R, A, C | D8: I
B9: Any kind of Migration/Application-Database upgrades or data movement and post migration Activities - DC | C9: R, A, C | D9: I
B10: DNS Management - DC | C10: R, A, C | D10: I
B11: For HA for Application/Database level | C11: R,A | D11: I,C
B12: Basic Infra monitoring – covers visibility upto resource used against allocated for VMs (For DC) | C12: C, I | D12: R, A
B13: Upgradation of resources to meet the performance (if required) | C13: R, A | D13: I, C
B14: Note: R -> Responsible; A -> Accountable; C -> Consulted & I -> Informed
B16: Assumptions :
B17: • The sizing is provided as per Client/Partner's inputs, based on which the commercials are proposed, if in case any additional resources or services are required which are not mentioned in this commercials/BoM and rate card, prices for the same will be shared and such additional resource or service will be charged addition to the mentioned BoM and Prices.
B18: • For any other additional/optional component/service charge, please refer to the Rate Card
B19: • In this commercial proposal, there is no migration/Upgrade scope involved, hence if in case there is any kind of migration/upgrade activity to be undertaken by ESDS team then ESDS would first analyze the scope and then submit the effort estimate and would be charged over and above the prices mentioned in this proposal.
B20: • Initially we have proposed minimum Internet bandwidth/IPs/Disk IOPS/DC-DR Replication Link/VPNs. Based on actual requirement, we can upgrade/add additional resources and charges for the same would be additional.
B21: • In case client undergoes any audit (like PCI-DSS), there would be additional dedicated resources required to perform the compliances as per the audit policy and need to make changes and submit reports to get compliance done, so the charges for such services will be additional.
B22: • We've not included any SSL Certificate in commercials, if required same can be provisioned with additional cost at actual.
B23: • We're proposing our Private cloud platform with 2.5/2.6 GHz CPU & Client/Partner needs to size the infra accordingly.
B24: • DB license & Managmenet will be under clinet scope
B25: • For any customized OS template to be deployed on ESDS Cloud, ESDS will first evaluate the feasibility/security checks & deserves a right to decide whether same can be deployed on cloud or not.
B26: No GPU is included in this BOM
